{
 "cells": [
  {
   "cell_type": "code",
   "execution_count": 3,
   "id": "2a04dca4",
   "metadata": {},
   "outputs": [],
   "source": [
    "from tensorflow.python.keras.utils import np_utils\n",
    "from tensorflow.keras.datasets import mnist\n",
    "from tensorflow.keras.models import Sequential\n",
    "from tensorflow.keras.layers import Dense"
   ]
  },
  {
   "cell_type": "markdown",
   "id": "1c63280a",
   "metadata": {},
   "source": [
    "# mnist 데이터"
   ]
  },
  {
   "cell_type": "code",
   "execution_count": 9,
   "id": "0a719da6",
   "metadata": {},
   "outputs": [
    {
     "name": "stdout",
     "output_type": "stream",
     "text": [
      "((60000, 28, 28), (60000,)) ((10000, 28, 28), (10000,))\n"
     ]
    }
   ],
   "source": [
    "(train_images, train_labels),(test_images, test_labels) = mnist.load_data()\n",
    "print((train_images.shape, train_labels.shape),(test_images.shape, test_labels.shape))"
   ]
  },
  {
   "cell_type": "code",
   "execution_count": 10,
   "id": "495d7b02",
   "metadata": {},
   "outputs": [],
   "source": [
    "train_images = train_images.reshape(train_images.shape[0],784).astype('float32')/255.0\n",
    "test_images = test_images.reshape(test_images.shape[0],784).astype('float32')/255.0\n",
    "\n",
    "train_labels = np_utils.to_categorical(train_labels) # One-Hot Encoding\n",
    "test_labels = np_utils.to_categorical(test_labels) # One-Hot Encoding"
   ]
  },
  {
   "cell_type": "markdown",
   "id": "f0adee59",
   "metadata": {},
   "source": [
    "# 모델"
   ]
  },
  {
   "cell_type": "code",
   "execution_count": 17,
   "id": "e105492b",
   "metadata": {},
   "outputs": [],
   "source": [
    "model = Sequential()\n",
    "model.add(Dense(256, activation='relu')) # units=256, activation='relu'\n",
    "model.add(Dense(256, activation='relu')) # units=256, activation='relu'\n",
    "model.add(Dense(256, activation='relu')) # units=256, activation='relu'\n",
    "model.add(Dense(10, activation='softmax')) # units=10, activation='softmax'\n",
    "model.compile(loss='categorical_crossentropy', optimizer='sgd', metrics=['accuracy'])"
   ]
  },
  {
   "cell_type": "code",
   "execution_count": 21,
   "id": "59c7db51",
   "metadata": {},
   "outputs": [
    {
     "name": "stdout",
     "output_type": "stream",
     "text": [
      "Model: \"sequential_5\"\n",
      "_________________________________________________________________\n",
      " Layer (type)                Output Shape              Param #   \n",
      "=================================================================\n",
      " dense_20 (Dense)            (None, 256)               7424      \n",
      "                                                                 \n",
      " dense_21 (Dense)            (None, 256)               65792     \n",
      "                                                                 \n",
      " dense_22 (Dense)            (None, 256)               65792     \n",
      "                                                                 \n",
      " dense_23 (Dense)            (None, 10)                2570      \n",
      "                                                                 \n",
      "=================================================================\n",
      "Total params: 141578 (553.04 KB)\n",
      "Trainable params: 141578 (553.04 KB)\n",
      "Non-trainable params: 0 (0.00 Byte)\n",
      "_________________________________________________________________\n"
     ]
    }
   ],
   "source": [
    "model.build(train_images.shape)\n",
    "model.summary()"
   ]
  },
  {
   "cell_type": "markdown",
   "id": "c6504581",
   "metadata": {},
   "source": [
    "### 모델 학습"
   ]
  },
  {
   "cell_type": "code",
   "execution_count": 22,
   "id": "f69cb741",
   "metadata": {},
   "outputs": [
    {
     "name": "stdout",
     "output_type": "stream",
     "text": [
      "Epoch 1/5\n"
     ]
    },
    {
     "ename": "ValueError",
     "evalue": "in user code:\n\n    File \"C:\\Users\\user\\anaconda3\\Lib\\site-packages\\keras\\src\\engine\\training.py\", line 1338, in train_function  *\n        return step_function(self, iterator)\n    File \"C:\\Users\\user\\anaconda3\\Lib\\site-packages\\keras\\src\\engine\\training.py\", line 1322, in step_function  **\n        outputs = model.distribute_strategy.run(run_step, args=(data,))\n    File \"C:\\Users\\user\\anaconda3\\Lib\\site-packages\\keras\\src\\engine\\training.py\", line 1303, in run_step  **\n        outputs = model.train_step(data)\n    File \"C:\\Users\\user\\anaconda3\\Lib\\site-packages\\keras\\src\\engine\\training.py\", line 1080, in train_step\n        y_pred = self(x, training=True)\n    File \"C:\\Users\\user\\anaconda3\\Lib\\site-packages\\keras\\src\\utils\\traceback_utils.py\", line 70, in error_handler\n        raise e.with_traceback(filtered_tb) from None\n    File \"C:\\Users\\user\\anaconda3\\Lib\\site-packages\\keras\\src\\engine\\input_spec.py\", line 280, in assert_input_compatibility\n        raise ValueError(\n\n    ValueError: Exception encountered when calling layer 'sequential_5' (type Sequential).\n    \n    Input 0 of layer \"dense_20\" is incompatible with the layer: expected axis -1 of input shape to have value 28, but received input with shape (32, 784)\n    \n    Call arguments received by layer 'sequential_5' (type Sequential):\n      • inputs=tf.Tensor(shape=(32, 784), dtype=float32)\n      • training=True\n      • mask=None\n",
     "output_type": "error",
     "traceback": [
      "\u001b[1;31m---------------------------------------------------------------------------\u001b[0m",
      "\u001b[1;31mValueError\u001b[0m                                Traceback (most recent call last)",
      "Cell \u001b[1;32mIn[22], line 1\u001b[0m\n\u001b[1;32m----> 1\u001b[0m model\u001b[38;5;241m.\u001b[39mfit(train_images, train_labels, epochs\u001b[38;5;241m=\u001b[39m\u001b[38;5;241m5\u001b[39m, batch_size\u001b[38;5;241m=\u001b[39m\u001b[38;5;241m32\u001b[39m, verbose\u001b[38;5;241m=\u001b[39m\u001b[38;5;241m1\u001b[39m)\n",
      "File \u001b[1;32m~\\anaconda3\\Lib\\site-packages\\keras\\src\\utils\\traceback_utils.py:70\u001b[0m, in \u001b[0;36mfilter_traceback.<locals>.error_handler\u001b[1;34m(*args, **kwargs)\u001b[0m\n\u001b[0;32m     67\u001b[0m     filtered_tb \u001b[38;5;241m=\u001b[39m _process_traceback_frames(e\u001b[38;5;241m.\u001b[39m__traceback__)\n\u001b[0;32m     68\u001b[0m     \u001b[38;5;66;03m# To get the full stack trace, call:\u001b[39;00m\n\u001b[0;32m     69\u001b[0m     \u001b[38;5;66;03m# `tf.debugging.disable_traceback_filtering()`\u001b[39;00m\n\u001b[1;32m---> 70\u001b[0m     \u001b[38;5;28;01mraise\u001b[39;00m e\u001b[38;5;241m.\u001b[39mwith_traceback(filtered_tb) \u001b[38;5;28;01mfrom\u001b[39;00m \u001b[38;5;28;01mNone\u001b[39;00m\n\u001b[0;32m     71\u001b[0m \u001b[38;5;28;01mfinally\u001b[39;00m:\n\u001b[0;32m     72\u001b[0m     \u001b[38;5;28;01mdel\u001b[39;00m filtered_tb\n",
      "File \u001b[1;32m~\\AppData\\Local\\Temp\\__autograph_generated_fileurjr12gu.py:15\u001b[0m, in \u001b[0;36mouter_factory.<locals>.inner_factory.<locals>.tf__train_function\u001b[1;34m(iterator)\u001b[0m\n\u001b[0;32m     13\u001b[0m \u001b[38;5;28;01mtry\u001b[39;00m:\n\u001b[0;32m     14\u001b[0m     do_return \u001b[38;5;241m=\u001b[39m \u001b[38;5;28;01mTrue\u001b[39;00m\n\u001b[1;32m---> 15\u001b[0m     retval_ \u001b[38;5;241m=\u001b[39m ag__\u001b[38;5;241m.\u001b[39mconverted_call(ag__\u001b[38;5;241m.\u001b[39mld(step_function), (ag__\u001b[38;5;241m.\u001b[39mld(\u001b[38;5;28mself\u001b[39m), ag__\u001b[38;5;241m.\u001b[39mld(iterator)), \u001b[38;5;28;01mNone\u001b[39;00m, fscope)\n\u001b[0;32m     16\u001b[0m \u001b[38;5;28;01mexcept\u001b[39;00m:\n\u001b[0;32m     17\u001b[0m     do_return \u001b[38;5;241m=\u001b[39m \u001b[38;5;28;01mFalse\u001b[39;00m\n",
      "\u001b[1;31mValueError\u001b[0m: in user code:\n\n    File \"C:\\Users\\user\\anaconda3\\Lib\\site-packages\\keras\\src\\engine\\training.py\", line 1338, in train_function  *\n        return step_function(self, iterator)\n    File \"C:\\Users\\user\\anaconda3\\Lib\\site-packages\\keras\\src\\engine\\training.py\", line 1322, in step_function  **\n        outputs = model.distribute_strategy.run(run_step, args=(data,))\n    File \"C:\\Users\\user\\anaconda3\\Lib\\site-packages\\keras\\src\\engine\\training.py\", line 1303, in run_step  **\n        outputs = model.train_step(data)\n    File \"C:\\Users\\user\\anaconda3\\Lib\\site-packages\\keras\\src\\engine\\training.py\", line 1080, in train_step\n        y_pred = self(x, training=True)\n    File \"C:\\Users\\user\\anaconda3\\Lib\\site-packages\\keras\\src\\utils\\traceback_utils.py\", line 70, in error_handler\n        raise e.with_traceback(filtered_tb) from None\n    File \"C:\\Users\\user\\anaconda3\\Lib\\site-packages\\keras\\src\\engine\\input_spec.py\", line 280, in assert_input_compatibility\n        raise ValueError(\n\n    ValueError: Exception encountered when calling layer 'sequential_5' (type Sequential).\n    \n    Input 0 of layer \"dense_20\" is incompatible with the layer: expected axis -1 of input shape to have value 28, but received input with shape (32, 784)\n    \n    Call arguments received by layer 'sequential_5' (type Sequential):\n      • inputs=tf.Tensor(shape=(32, 784), dtype=float32)\n      • training=True\n      • mask=None\n"
     ]
    }
   ],
   "source": [
    "model.fit(train_images, train_labels, epochs=5, batch_size=32, verbose=1)"
   ]
  },
  {
   "cell_type": "markdown",
   "id": "a8abb85a",
   "metadata": {},
   "source": [
    "### 모델 테스트"
   ]
  },
  {
   "cell_type": "code",
   "execution_count": null,
   "id": "75a13f2b",
   "metadata": {},
   "outputs": [],
   "source": [
    "_, accuracy = model.evaluate(test_images, test_labels)\n",
    "print(accuracy)"
   ]
  },
  {
   "cell_type": "code",
   "execution_count": null,
   "id": "932d3600",
   "metadata": {},
   "outputs": [],
   "source": []
  },
  {
   "cell_type": "code",
   "execution_count": null,
   "id": "761910df",
   "metadata": {},
   "outputs": [],
   "source": []
  }
 ],
 "metadata": {
  "kernelspec": {
   "display_name": "Python 3 (ipykernel)",
   "language": "python",
   "name": "python3"
  },
  "language_info": {
   "codemirror_mode": {
    "name": "ipython",
    "version": 3
   },
   "file_extension": ".py",
   "mimetype": "text/x-python",
   "name": "python",
   "nbconvert_exporter": "python",
   "pygments_lexer": "ipython3",
   "version": "3.11.5"
  }
 },
 "nbformat": 4,
 "nbformat_minor": 5
}
